Workbook
Name aasta: SKP!$G$23:$G$382
Name Ideaalkaal__mid: Ideaal!$C$17
Name kaal__m: Ideaal!$C$14
Name kehamassiindeks__kind: Ideaal!$C$19
Name kõik_kaalud: Ideaal!$S$29:$AH$29
Name kõik_pikkused: Ideaal!$R$30:$R$40
Name lähteandmed: Ideaal!$C$11:$C$14
Name maakond: SKP!$F$23:$F$382
Name maakondade_rahvaarvud: SKP!$H$23:$H$382
Name majandusnäitajad_el._kohta: SKP!$I$23:$I$382
Name majandussektorid: SKP!$C$23:$C$382
Name pikkus__l: Ideaal!$C$13
Name rahvastik_aastad: Rahvastik!$C$3:$J$3
Name rahvastik_maakonnad: Rahvastik!$B$4:$B$18
Name rahvastik_tabel: Rahvastik!$C$4:$J$18
Name rasvaprotsent__r: Ideaal!$C$18
Name SKP_aasta: SKP!$G$23:$G$382
Name SKP_andmed: SKP!$C$22:$I$382
Name SKP_maakond: SKP!$F$23:$F$382
Name sugu: Ideaal!$C$11
Name sõnaline_hinnang: Ideaal!$C$24
Name Tabel_A: Pivot!$C$10:$M$30
Name Tabel_B: Pivot!$C$34:$E$51
Name Tabel_C: Pivot!$O$10:$T$21
Name tabel_kmi: Ideaal!$S$30:$AH$40
Name tihedus__p: Ideaal!$C$20
Name töötajate_tabel: Töötajad!$A$2:$E$100
Name vanus__t: Ideaal!$C$12
Name väljamõeldud_inimesed: Töötajad!$A$1:$E$100
Name Väärtus_jooksevhindades__miljonit_eurot: SKP!$D$23:$D$382
Name y: Ideaal!$C$21

Sheet Tabeliobjekt
A1: ANDMED | B1: ARVUTUSED | D1: töötajate andmete kuvamine ning neile komandeeringutasu määramine vastava kuupäevaga. Valideerimine loeteluga(list) ja ilma, INDEX MATCH kasutus, lahtritele tingimuste määramine
A2: väljamõeldud_inimesed | B2: Tabeliobjekt!E16:F21
C15: Määrake nimi ning komandeeringutasu vastava kuupäevaga
C16: töötaja | D16: kuupäev | E16: amet | F16: isikukood | G16: komandeeringutasu
C17: Mirja Bergmann | D17: 46260 | E17: =INDEX(töötajate_tabel,MATCH($C17,Töötajad!$A$2:$A$100,0),MATCH(Töötajad!$D$1,Töötajad!$A$1:$E$1,0)) -> koristaja | F17: =INDEX(töötajate_tabel,MATCH($C17,Töötajad!$A$2:$A$100,0),MATCH(Töötajad!$B$1,Töötajad!$A$1:$E$1,0)) -> 46309091292 | G17: 1
C18: Meelis Petrov | D18: 46261 | E18: =INDEX(töötajate_tabel,MATCH($C18,Töötajad!$A$2:$A$100,0),MATCH(Töötajad!$D$1,Töötajad!$A$1:$E$1,0)) -> tööline | F18: =INDEX(töötajate_tabel,MATCH($C18,Töötajad!$A$2:$A$100,0),MATCH(Töötajad!$B$1,Töötajad!$A$1:$E$1,0)) -> 50209191696 | G18: 1
C19: Riho Kuusk | D19: 46262 | E19: =INDEX(töötajate_tabel,MATCH($C19,Töötajad!$A$2:$A$100,0),MATCH(Töötajad!$D$1,Töötajad!$A$1:$E$1,0)) -> tööline | F19: =INDEX(töötajate_tabel,MATCH($C19,Töötajad!$A$2:$A$100,0),MATCH(Töötajad!$B$1,Töötajad!$A$1:$E$1,0)) -> 36209121746 | G19: 11
C20: Marko Erikson | D20: 46263 | E20: =INDEX(töötajate_tabel,MATCH($C20,Töötajad!$A$2:$A$100,0),MATCH(Töötajad!$D$1,Töötajad!$A$1:$E$1,0)) -> meister | F20: =INDEX(töötajate_tabel,MATCH($C20,Töötajad!$A$2:$A$100,0),MATCH(Töötajad!$B$1,Töötajad!$A$1:$E$1,0)) -> 36304040224 | G20: 1
C21: Mirja Bergmann | D21: 46264 | E21: =INDEX(töötajate_tabel,MATCH($C21,Töötajad!$A$2:$A$100,0),MATCH(Töötajad!$D$1,Töötajad!$A$1:$E$1,0)) -> koristaja | F21: =INDEX(töötajate_tabel,MATCH($C21,Töötajad!$A$2:$A$100,0),MATCH(Töötajad!$B$1,Töötajad!$A$1:$E$1,0)) -> 46309091292 | G21: 1
C22: Total | D22: =SUBTOTAL(103,Table1[kuupäev]) -> 5 | E22: =SUBTOTAL(103,Table1[amet]) -> 5 | F22: =SUBTOTAL(103,Table1[isikukood]) -> 5 | G22: =SUBTOTAL(109,Table1[komandeeringutasu]) -> 15

Sheet SKP
D1: IF tingimuse kasutus, INDEX MATCH, lahtrite täitmine valemite abil, advanced filter kasutamine. RAA0051: SISEMAJANDUSE KOGUPRODUKT (ESA 2010) --- Aasta, Maakond, majandussektor ning näitaja
B2: ANDMED
B3: Rahvastik!A1
B5: ARVUTUSED
B6: SKP!F21:I382
B8: ADVANCED FILTER
B9: SKP!D9:J18 | D9: tingimus | I9: haldusüksuste nimekiri vastavalt tingimustele | J9: advanced filter kasutamise kirjeldus
D10: aasta | E10: aasta | F10: majandussektorid | G10: majandusnäitajad el. kohta | I10: Hiiu maakond | J10: andmete hulk=SKP_andmed
D11: >=2012 | E11: <=2015 | F11: Põllumajandus, metsamajandus ja kalapüük | G11: >900 | I11: Jõgeva maakond | J11: kriteeriumipiirkond=$G$14:$J$16
I12: Järva maakond | J12: kopeerimise asukoht=$K$21
I13: Lääne-Viru maakond | J13: Unique records only
I14: Põlva maakond
I15: Viljandi maakond
I16: Valga maakond
I17: Võru maakond
I18: Rapla maakond
A21: andmed | F21: arvutused (k.a tabel andmed põhjal)
A22: Aasta info | B22: Maakonnainfo | C22: majandussektorid | D22: Väärtus jooksevhindades, miljonit eurot | F22: maakond | G22: aasta | H22: maakondade rahvaarvud | I22: majandusnäitajad el. kohta
A23: 2012 | B23: Harju maakond | C23: Põllumajandus, metsamajandus ja kalapüük | D23: 98.82 | F23: =IF(NOT(ISBLANK(B23)),B23,F22) -> Harju maakond | G23: =_xlfn.NUMBERVALUE(IF(NOT(ISBLANK(A23)),A23,G22)) -> 2012 | H23: {=INDEX(rahvastik_tabel,MATCH(SKP_maakond,rahvastik_maakonnad,0),MATCH(SKP_aasta,rahvastik_aastad,0))} -> 566741 | I23: {=ROUND((Väärtus_jooksevhindades__miljonit_eurot*1000000)/maakondade_rahvaarvud,2)} -> 174.37
C24: Tööstus ja ehitus* | D24: 2286.81 | F24: =IF(NOT(ISBLANK(B24)),B24,F23) -> Harju maakond | G24: =_xlfn.NUMBERVALUE(IF(NOT(ISBLANK(A24)),A24,G23)) -> 2012 | H24: 566741 | I24: 4035.02
C25: Teenused* | D25: 7557.54 | F25: =IF(NOT(ISBLANK(B25)),B25,F24) -> Harju maakond | G25: =_xlfn.NUMBERVALUE(IF(NOT(ISBLANK(A25)),A25,G24)) -> 2012 | H25: 566741 | I25: 13335.09
B26: Hiiu maakond | C26: Põllumajandus, metsamajandus ja kalapüük | D26: 8.68 | F26: =IF(NOT(ISBLANK(B26)),B26,F25) -> Hiiu maakond | G26: =_xlfn.NUMBERVALUE(IF(NOT(ISBLANK(A26)),A26,G25)) -> 2012 | H26: 8620 | I26: 1006.96
C27: Tööstus ja ehitus* | D27: 21.15 | F27: =IF(NOT(ISBLANK(B27)),B27,F26) -> Hiiu maakond | G27: =_xlfn.NUMBERVALUE(IF(NOT(ISBLANK(A27)),A27,G26)) -> 2012 | H27: 8620 | I27: 2453.6
C28: Teenused* | D28: 27.91 | F28: =IF(NOT(ISBLANK(B28)),B28,F27) -> Hiiu maakond | G28: =_xlfn.NUMBERVALUE(IF(NOT(ISBLANK(A28)),A28,G27)) -> 2012 | H28: 8620 | I28: 3237.82
B29: Ida-Viru maakond | C29: Põllumajandus, metsamajandus ja kalapüük | D29: 18.43 | F29: =IF(NOT(ISBLANK(B29)),B29,F28) -> Ida-Viru maakond | G29: =_xlfn.NUMBERVALUE(IF(NOT(ISBLANK(A29)),A29,G28)) -> 2012 | H29: 153716 | I29: 119.9
C30: Tööstus ja ehitus* | D30: 650.86 | F30: =IF(NOT(ISBLANK(B30)),B30,F29) -> Ida-Viru maakond | G30: =_xlfn.NUMBERVALUE(IF(NOT(ISBLANK(A30)),A30,G29)) -> 2012 | H30: 153716 | I30: 4234.17
C31: Teenused* | D31: 475.93 | F31: =IF(NOT(ISBLANK(B31)),B31,F30) -> Ida-Viru maakond | G31: =_xlfn.NUMBERVALUE(IF(NOT(ISBLANK(A31)),A31,G30)) -> 2012 | H31: 153716 | I31: 3096.16
B32: Jõgeva maakond | C32: Põllumajandus, metsamajandus ja kalapüük | D32: 48.05 | F32: =IF(NOT(ISBLANK(B32)),B32,F31) -> Jõgeva maakond | G32: =_xlfn.NUMBERVALUE(IF(NOT(ISBLANK(A32)),A32,G31)) -> 2012 | H32: 31967 | I32: 1503.11
C33: Tööstus ja ehitus* | D33: 52.5 | F33: =IF(NOT(ISBLANK(B33)),B33,F32) -> Jõgeva maakond | G33: =_xlfn.NUMBERVALUE(IF(NOT(ISBLANK(A33)),A33,G32)) -> 2012 | H33: 31967 | I33: 1642.32
C34: Teenused* | D34: 75.22 | F34: =IF(NOT(ISBLANK(B34)),B34,F33) -> Jõgeva maakond | G34: =_xlfn.NUMBERVALUE(IF(NOT(ISBLANK(A34)),A34,G33)) -> 2012 | H34: 31967 | I34: 2353.05
B35: Järva maakond | C35: Põllumajandus, metsamajandus ja kalapüük | D35: 37.29 | F35: =IF(NOT(ISBLANK(B35)),B35,F34) -> Järva maakond | G35: =_xlfn.NUMBERVALUE(IF(NOT(ISBLANK(A35)),A35,G34)) -> 2012 | H35: 31204 | I35: 1195.04
C36: Tööstus ja ehitus* | D36: 99.23 | F36: =IF(NOT(ISBLANK(B36)),B36,F35) -> Järva maakond | G36: =_xlfn.NUMBERVALUE(IF(NOT(ISBLANK(A36)),A36,G35)) -> 2012 | H36: 31204 | I36: 3180.04
C37: Teenused* | D37: 102.15 | F37: =IF(NOT(ISBLANK(B37)),B37,F36) -> Järva maakond | G37: =_xlfn.NUMBERVALUE(IF(NOT(ISBLANK(A37)),A37,G36)) -> 2012 | H37: 31204 | I37: 3273.62
B38: Lääne maakond | C38: Põllumajandus, metsamajandus ja kalapüük | D38: 17.32 | F38: =IF(NOT(ISBLANK(B38)),B38,F37) -> Lääne maakond | G38: =_xlfn.NUMBERVALUE(IF(NOT(ISBLANK(A38)),A38,G37)) -> 2012 | H38: 24734 | I38: 700.25
C39: Tööstus ja ehitus* | D39: 61.22 | F39: =IF(NOT(ISBLANK(B39)),B39,F38) -> Lääne maakond | G39: =_xlfn.NUMBERVALUE(IF(NOT(ISBLANK(A39)),A39,G38)) -> 2012 | H39: 24734 | I39: 2475.14
C40: Teenused* | D40: 91.29 | F40: =IF(NOT(ISBLANK(B40)),B40,F39) -> Lääne maakond | G40: =_xlfn.NUMBERVALUE(IF(NOT(ISBLANK(A40)),A40,G39)) -> 2012 | H40: 24734 | I40: 3690.87
B41: Lääne-Viru maakond | C41: Põllumajandus, metsamajandus ja kalapüük | D41: 59.99 | F41: =IF(NOT(ISBLANK(B41)),B41,F40) -> Lääne-Viru maakond | G41: =_xlfn.NUMBERVALUE(IF(NOT(ISBLANK(A41)),A41,G40)) -> 2012 | H41: 61154 | I41: 980.97
C42: Tööstus ja ehitus* | D42: 210.6 | F42: =IF(NOT(ISBLANK(B42)),B42,F41) -> Lääne-Viru maakond | G42: =_xlfn.NUMBERVALUE(IF(NOT(ISBLANK(A42)),A42,G41)) -> 2012 | H42: 61154 | I42: 3443.76
C43: Teenused* | D43: 219.95 | F43: =IF(NOT(ISBLANK(B43)),B43,F42) -> Lääne-Viru maakond | G43: =_xlfn.NUMBERVALUE(IF(NOT(ISBLANK(A43)),A43,G42)) -> 2012 | H43: 61154 | I43: 3596.66
B44: Põlva maakond | C44: Põllumajandus, metsamajandus ja kalapüük | D44: 30.02 | F44: =IF(NOT(ISBLANK(B44)),B44,F43) -> Põlva maakond | G44: =_xlfn.NUMBERVALUE(IF(NOT(ISBLANK(A44)),A44,G43)) -> 2012 | H44: 28026 | I44: 1071.15
...

Sheet Pivot
E1: SKP andmetest tehtud liigendtabelid: A) Keskmine SKP elaniku kohta (2014–2016) sektorite ja haldusüksuste lõikes. B) SKP elaniku kohta (2013, 2018) 500 € vahemike kaupa (maakondade arv). C) Sektori „Põllumajandus, metsamajandus ja kalapüük” SKP elaniku kohta aastate kaupa: järjestus, osakaal ja erinevus äärmusväärtustest.
C2: ANDMED | D2: SKP_andmed
C3: Tabel A | D3: Tabel_A
C4: Tabel B | D4: Tabel_B
C5: Tabel C | D5: Tabel_C
C10: keskmine SKP elaniku kohta aastatel 2014–2016 majandussektorite ja haldusüksuste lõikes | O10: Majandussektori „Põllumajandus, metsamajandus ja kalapüük” SKP elaniku kohta aastate kaupa, järjestatuna väärtuse järgi, näidates iga aasta osakaalu kõigi aastate kogusummast ning protsentuaalset erinevust suurima ja väikseima aastaväärtuse suhtes.
C12: Average of majandusnäitajad el. kohta | D12: Column Labels | O12: Row Labels | P12: Sum of Väärtus jooksevhindades, miljonit eurot | Q12: kõikide aastate kogusummast protsentuaalselt | R12: järjestatud suuremast väiksemani | S12: protsentuaalne erinevus suurimast | T12: protsentuaalne erinevus väikseimast
D13: 2014 | G13: 2015 | J13: 2016 | M13: Grand Total | O13: Põllumajandus, metsamajandus ja kalapüük | P13: 4622.39 | Q13: 1
C14: Row Labels | D14: Põllumajandus, metsamajandus ja kalapüük | E14: Teenused* | F14: Tööstus ja ehitus* | G14: Põllumajandus, metsamajandus ja kalapüük | H14: Teenused* | I14: Tööstus ja ehitus* | J14: Põllumajandus, metsamajandus ja kalapüük | K14: Teenused* | L14: Tööstus ja ehitus* | O14: 2012 | P14: 594.03 | Q14: 0.12281117 | R14: 6 | S14: -0.18484112 | T14: 0.2412609
C15: Harju maakond | D15: 137.82 | E15: 15264.44 | F15: 4411.02 | G15: 96.51 | H15: 15793.44 | I15: 4432.41 | J15: 91.49 | K15: 16482.59 | L15: 4801.33 | M15: 6834.5611 | O15: 2013 | P15: 583.98 | Q15: 0.12629277 | R15: 4 | S15: -0.16173201 | T15: 0.27644967
C16: Hiiu maakond | D16: 906.97 | E16: 3143.56 | F16: 2472.93 | G16: 1014.91 | H16: 3489.86 | I16: 2853.65 | J16: 882.54 | K16: 3506.63 | L16: 3208.17 | M16: 2386.58 | O16: 2014 | P16: 634.38 | Q16: 0.13782226 | R16: 2 | S16: -0.085205005 | T16: 0.39297907
C17: Ida-Viru maakond | D17: 92.52 | E17: 3128.52 | F17: 5067.27 | G17: 93.23 | H17: 3249.73 | I17: 4188.03 | J17: 72.01 | K17: 3279.59 | L17: 3936.63 | M17: 2567.5033 | O17: 2015 | P17: 589.67 | Q17: 0.13414811 | R17: 3 | S17: -0.1095922 | T17: 0.35584413
C18: Jõgeva maakond | D18: 1569.75 | E18: 2294.43 | F18: 1899.5 | G18: 1392.95 | H18: 2624.43 | I18: 1993.45 | J18: 943.83 | K18: 2503.35 | L18: 2223.78 | M18: 1938.3856 | O18: 2016 | P18: 459.66 | Q18: 0.098940655 | R18: 8 | S18: -0.34328159
C19: Järva maakond | D19: 1203.94 | E19: 3430.4 | F19: 2991.29 | G19: 1110.63 | H19: 3467.4 | I19: 2977.52 | J19: 681.23 | K19: 3558.89 | L19: 3500.93 | M19: 2546.9144 | O19: 2017 | P19: 566.48 | Q19: 0.12420774 | R19: 5 | S19: -0.17557138 | T19: 0.25537615
C20: Lääne maakond | D20: 619.99 | E20: 3890.15 | F20: 2176.54 | G20: 647.28 | H20: 3852.1 | I20: 2081.43 | J20: 483.32 | K20: 3632.22 | L20: 2279.09 | M20: 2184.68 | O20: 2018 | P20: 493.34 | Q20: 0.10511813 | R20: 7 | S20: -0.3022786 | T20: 0.062436192
C21: Lääne-Viru maakond | D21: 1057.01 | E21: 3165.16 | F21: 3774.9 | G21: 970.88 | H21: 3436.71 | I21: 3684.01 | J21: 679.37 | K21: 3521.95 | L21: 3988.94 | M21: 2697.6589 | O21: 2019 | P21: 700.85 | Q21: 0.15065918 | R21: 1 | T21: 0.52272266
C22: Põlva maakond | D22: 928.69 | E22: 2967.69 | F22: 1573.75 | G22: 878.71 | H22: 3293.61 | I22: 1605.44 | J22: 506.06 | K22: 3252.18 | L22: 1368.63 | M22: 1819.4178
C23: Pärnu maakond | D23: 797.55 | E23: 4793.73 | F23: 2895.48 | G23: 788.96 | H23: 5217.91 | I23: 3253.47 | J23: 681.35 | K23: 5566.35 | L23: 3486.15 | M23: 3053.4389
C24: Rapla maakond | D24: 1114.32 | E24: 3610.85 | F24: 2026.76 | G24: 1018.7 | H24: 3849.17 | I24: 2317.63 | J24: 823.47 | K24: 4026.88 | L24: 2403.65 | M24: 2354.6033
C25: Saare maakond | D25: 535.65 | E25: 5069.59 | F25: 3238.13 | G25: 505.58 | H25: 5655.4 | I25: 3240.08 | J25: 341.99 | K25: 7466.32 | L25: 3274.69 | M25: 3258.6033
C26: Tartu maakond | D26: 502.21 | E26: 7755.01 | F26: 3097.55 | G26: 494.13 | H26: 8128.58 | I26: 3255.38 | J26: 429.23 | K26: 9359.32 | L26: 3642.82 | M26: 4073.8033
C27: Valga maakond | D27: 1100.21 | E27: 2888.06 | F27: 2381.03 | G27: 1084.02 | H27: 3109.8 | I27: 2426.2 | J27: 905.52 | K27: 4242.56 | L27: 2799.44 | M27: 2326.3156
C28: Viljandi maakond | D28: 1684.85 | E28: 3941.15 | F28: 3080.5 | G28: 1593.7 | H28: 3984.68 | I28: 3273.35 | J28: 1262.83 | K28: 4078.32 | L28: 3272.94 | M28: 2908.0356
C29: Võru maakond | D29: 997.13 | E29: 3203.79 | F29: 2699.69 | G29: 1205.23 | H29: 3149.04 | I29: 2919.03 | J29: 726.75 | K29: 3495.72 | L29: 2824.6 | M29: 2357.8867
C30: Grand Total | D30: 883.24067 | E30: 4569.7687 | F30: 2919.0893 | G30: 859.69467 | H30: 4820.124 | I30: 2966.7387 | J30: 634.066 | K30: 5198.1913 | L30: 3134.1193 | M30: 2887.2259
C34: SKP elaniku kohta, rühmitatuna 500-eurostesse vahemikesse, kajastades maakondade arvu igas vahemikus aastatel 2013 ja 2018.
C35: Count of maakond | D35: Column Labels
D36: Teenused*
C37: Row Labels | D37: 2013 | E37: 2018
C38: 2000-2500 | D38: 1
C39: 2500-3000 | D39: 3
C40: 3000-3500 | D40: 4
C41: 3500-4000 | D41: 3 | E41: 4
C42: 4000-4500 | E42: 2
C43: 4500-5000 | D43: 2 | E43: 1
C44: 5000-5500 | E44: 3
C45: 5500-6000 | E45: 1
C46: 6500-7000 | E46: 1
C47: 7000-7500 | D47: 1 | E47: 1
C48: 10500-11000 | E48: 1
...

Sheet Subtotal
C1: Majandussektori "Tööstus ja ehitus" andmete leidmine aastatel 2012 - 2014 ning keskmine SKP elaniku kohta maakondade lõikes arendatud filtri abil
A2: ANDMED
A3: SKP_andmed
C12: tingimuspiirkond | H12: arendatud filtri kirjeldus
C13: majandussektorid | D13: aasta | E13: aasta | H13: List Range: SKP_andmed
C14: Tööstus ja ehitus* | D14: <=2014 | E14: >=2012 | H14: Criteria Range:$C$13:$E$14
H15: Copy To:$C$17
C17: majandussektorid | D17: Väärtus jooksevhindades, miljonit eurot | E17: maakond | F17: aasta | G17: maakondade rahvaarvud | H17: majandusnäitajad el. kohta
C18: Tööstus ja ehitus* | D18: 2286.81 | E18: Harju maakond | F18: 2012 | G18: 566741 | H18: 4035.02
C19: Tööstus ja ehitus* | D19: 2371.85 | E19: Harju maakond | F19: 2013 | G19: 567967 | H19: 4176.03
C20: Tööstus ja ehitus* | D20: 2523.56 | E20: Harju maakond | F20: 2014 | G20: 572103 | H20: 4411.02
C21: Harju maakonna keskmine SKP ühe elaniku kohta | H21: =SUBTOTAL(1,H18:H20) -> 4207.3567
C22: Tööstus ja ehitus* | D22: 21.15 | E22: Hiiu maakond | F22: 2012 | G22: 8620 | H22: 2453.6
C23: Tööstus ja ehitus* | D23: 21.33 | E23: Hiiu maakond | F23: 2013 | G23: 8638 | H23: 2469.32
C24: Tööstus ja ehitus* | D24: 21.24 | E24: Hiiu maakond | F24: 2014 | G24: 8589 | H24: 2472.93
C25: Hiiu maakonna keskmine SKP ühe elaniku kohta | H25: =SUBTOTAL(1,H22:H24) -> 2465.2833
C26: Tööstus ja ehitus* | D26: 650.86 | E26: Ida-Viru maakond | F26: 2012 | G26: 153716 | H26: 4234.17
C27: Tööstus ja ehitus* | D27: 801.27 | E27: Ida-Viru maakond | F27: 2013 | G27: 151909 | H27: 5274.67
C28: Tööstus ja ehitus* | D28: 757.47 | E28: Ida-Viru maakond | F28: 2014 | G28: 149483 | H28: 5067.27
C29: Ida-Viru maakonna keskmine SKP ühe elaniku kohta | H29: =SUBTOTAL(1,H26:H28) -> 4858.7033
C30: Tööstus ja ehitus* | D30: 52.5 | E30: Jõgeva maakond | F30: 2012 | G30: 31967 | H30: 1642.32
C31: Tööstus ja ehitus* | D31: 62.58 | E31: Jõgeva maakond | F31: 2013 | G31: 31587 | H31: 1981.19
C32: Tööstus ja ehitus* | D32: 59.16 | E32: Jõgeva maakond | F32: 2014 | G32: 31145 | H32: 1899.5
C33: Jõgeva maakonna keskmine SKP ühe elaniku kohta | H33: =SUBTOTAL(1,H30:H32) -> 1841.0033
C34: Tööstus ja ehitus* | D34: 99.23 | E34: Järva maakond | F34: 2012 | G34: 31204 | H34: 3180.04
C35: Tööstus ja ehitus* | D35: 92.82 | E35: Järva maakond | F35: 2013 | G35: 30913 | H35: 3002.62
C36: Tööstus ja ehitus* | D36: 91.01 | E36: Järva maakond | F36: 2014 | G36: 30425 | H36: 2991.29
C37: Järva maakonna keskmine SKP ühe elaniku kohta | H37: =SUBTOTAL(1,H34:H36) -> 3057.9833
C38: Tööstus ja ehitus* | D38: 61.22 | E38: Lääne maakond | F38: 2012 | G38: 24734 | H38: 2475.14
C39: Tööstus ja ehitus* | D39: 59.21 | E39: Lääne maakond | F39: 2013 | G39: 24622 | H39: 2404.76
C40: Tööstus ja ehitus* | D40: 52.94 | E40: Lääne maakond | F40: 2014 | G40: 24323 | H40: 2176.54
C41: Lääne maakonna keskmine SKP ühe elaniku kohta | H41: =SUBTOTAL(1,H38:H40) -> 2352.1467
C42: Tööstus ja ehitus* | D42: 210.6 | E42: Lääne-Viru maakond | F42: 2012 | G42: 61154 | H42: 3443.76
C43: Tööstus ja ehitus* | D43: 202.38 | E43: Lääne-Viru maakond | F43: 2013 | G43: 60518 | H43: 3344.13
C44: Tööstus ja ehitus* | D44: 224.92 | E44: Lääne-Viru maakond | F44: 2014 | G44: 59583 | H44: 3774.9
C45: Lääne-Viru maakonna keskmine SKP ühe elaniku kohta | H45: =SUBTOTAL(1,H42:H44) -> 3520.93
C46: Tööstus ja ehitus* | D46: 48.15 | E46: Põlva maakond | F46: 2012 | G46: 28026 | H46: 1718.05
C47: Tööstus ja ehitus* | D47: 46.62 | E47: Põlva maakond | F47: 2013 | G47: 27816 | H47: 1676.01
C48: Tööstus ja ehitus* | D48: 43.5 | E48: Põlva maakond | F48: 2014 | G48: 27641 | H48: 1573.75
C49: Põlva maakonna keskmine SKP ühe elaniku kohta | H49: =SUBTOTAL(1,H46:H48) -> 1655.9367
...

Sheet Koond
B1: majandussektori "Teenused" SKP elaniku kohta maakondade ja aastate lõikes leidmine, kasutades liigendtabelit ning SUMIFS valemit
B8: ANDMED
B9: SKP_andmed
M11: majandussektorid | N11: Teenused*
B13: maakond | C13: 2012 | D13: 2013 | E13: 2014 | F13: 2015 | G13: 2016 | H13: 2017 | I13: 2018 | J13: 2019 | M13: Sum of majandusnäitajad el. kohta | N13: Column Labels
B14: Harju maakond | C14: =SUMIFS(majandusnäitajad_el._kohta,maakond,$B14,aasta,C$13,majandussektorid,"Teenused*") -> 13335.09 | D14: =SUMIFS(majandusnäitajad_el._kohta,maakond,$B14,aasta,D$13,majandussektorid,"Teenused*") -> 14304.53 | E14: =SUMIFS(majandusnäitajad_el._kohta,maakond,$B14,aasta,E$13,majandussektorid,"Teenused*") -> 15264.44 | F14: =SUMIFS(majandusnäitajad_el._kohta,maakond,$B14,aasta,F$13,majandussektorid,"Teenused*") -> 15793.44 | G14: =SUMIFS(majandusnäitajad_el._kohta,maakond,$B14,aasta,G$13,majandussektorid,"Teenused*") -> 16482.59 | H14: =SUMIFS(majandusnäitajad_el._kohta,maakond,$B14,aasta,H$13,majandussektorid,"Teenused*") -> 18055.24 | I14: =SUMIFS(majandusnäitajad_el._kohta,maakond,$B14,aasta,I$13,majandussektorid,"Teenused*") -> 19486.02 | J14: =SUMIFS(majandusnäitajad_el._kohta,maakond,$B14,aasta,J$13,majandussektorid,"Teenused*") -> 21253.29 | M14: Row Labels | N14: 2012 | O14: 2013 | P14: 2014 | Q14: 2015 | R14: 2016 | S14: 2017 | T14: 2018 | U14: 2019
B15: Hiiu maakond | C15: =SUMIFS(majandusnäitajad_el._kohta,maakond,$B15,aasta,C$13,majandussektorid,"Teenused*") -> 3237.82 | D15: =SUMIFS(majandusnäitajad_el._kohta,maakond,$B15,aasta,D$13,majandussektorid,"Teenused*") -> 3212.55 | E15: =SUMIFS(majandusnäitajad_el._kohta,maakond,$B15,aasta,E$13,majandussektorid,"Teenused*") -> 3143.56 | F15: =SUMIFS(majandusnäitajad_el._kohta,maakond,$B15,aasta,F$13,majandussektorid,"Teenused*") -> 3489.86 | G15: =SUMIFS(majandusnäitajad_el._kohta,maakond,$B15,aasta,G$13,majandussektorid,"Teenused*") -> 3506.63 | H15: =SUMIFS(majandusnäitajad_el._kohta,maakond,$B15,aasta,H$13,majandussektorid,"Teenused*") -> 5152.65 | I15: =SUMIFS(majandusnäitajad_el._kohta,maakond,$B15,aasta,I$13,majandussektorid,"Teenused*") -> 5608.82 | J15: =SUMIFS(majandusnäitajad_el._kohta,maakond,$B15,aasta,J$13,majandussektorid,"Teenused*") -> 6098.86 | M15: Harju maakond | N15: 13335.09 | O15: 14304.53 | P15: 15264.44 | Q15: 15793.44 | R15: 16482.59 | S15: 18055.24 | T15: 19486.02 | U15: 21253.29
B16: Ida-Viru maakond | C16: =SUMIFS(majandusnäitajad_el._kohta,maakond,$B16,aasta,C$13,majandussektorid,"Teenused*") -> 3096.16 | D16: =SUMIFS(majandusnäitajad_el._kohta,maakond,$B16,aasta,D$13,majandussektorid,"Teenused*") -> 2969.08 | E16: =SUMIFS(majandusnäitajad_el._kohta,maakond,$B16,aasta,E$13,majandussektorid,"Teenused*") -> 3128.52 | F16: =SUMIFS(majandusnäitajad_el._kohta,maakond,$B16,aasta,F$13,majandussektorid,"Teenused*") -> 3249.73 | G16: =SUMIFS(majandusnäitajad_el._kohta,maakond,$B16,aasta,G$13,majandussektorid,"Teenused*") -> 3279.59 | H16: =SUMIFS(majandusnäitajad_el._kohta,maakond,$B16,aasta,H$13,majandussektorid,"Teenused*") -> 3426.4 | I16: =SUMIFS(majandusnäitajad_el._kohta,maakond,$B16,aasta,I$13,majandussektorid,"Teenused*") -> 3867.47 | J16: =SUMIFS(majandusnäitajad_el._kohta,maakond,$B16,aasta,J$13,majandussektorid,"Teenused*") -> 4242.95 | M16: Hiiu maakond | N16: 3237.82 | O16: 3212.55 | P16: 3143.56 | Q16: 3489.86 | R16: 3506.63 | S16: 5152.65 | T16: 5608.82 | U16: 6098.86
B17: Jõgeva maakond | C17: =SUMIFS(majandusnäitajad_el._kohta,maakond,$B17,aasta,C$13,majandussektorid,"Teenused*") -> 2353.05 | D17: =SUMIFS(majandusnäitajad_el._kohta,maakond,$B17,aasta,D$13,majandussektorid,"Teenused*") -> 2385.16 | E17: =SUMIFS(majandusnäitajad_el._kohta,maakond,$B17,aasta,E$13,majandussektorid,"Teenused*") -> 2294.43 | F17: =SUMIFS(majandusnäitajad_el._kohta,maakond,$B17,aasta,F$13,majandussektorid,"Teenused*") -> 2624.43 | G17: =SUMIFS(majandusnäitajad_el._kohta,maakond,$B17,aasta,G$13,majandussektorid,"Teenused*") -> 2503.35 | H17: =SUMIFS(majandusnäitajad_el._kohta,maakond,$B17,aasta,H$13,majandussektorid,"Teenused*") -> 3292.48 | I17: =SUMIFS(majandusnäitajad_el._kohta,maakond,$B17,aasta,I$13,majandussektorid,"Teenused*") -> 3955.49 | J17: =SUMIFS(majandusnäitajad_el._kohta,maakond,$B17,aasta,J$13,majandussektorid,"Teenused*") -> 4348.51 | M17: Ida-Viru maakond | N17: 3096.16 | O17: 2969.08 | P17: 3128.52 | Q17: 3249.73 | R17: 3279.59 | S17: 3426.4 | T17: 3867.47 | U17: 4242.95
B18: Järva maakond | C18: =SUMIFS(majandusnäitajad_el._kohta,maakond,$B18,aasta,C$13,majandussektorid,"Teenused*") -> 3273.62 | D18: =SUMIFS(majandusnäitajad_el._kohta,maakond,$B18,aasta,D$13,majandussektorid,"Teenused*") -> 3274.03 | E18: =SUMIFS(majandusnäitajad_el._kohta,maakond,$B18,aasta,E$13,majandussektorid,"Teenused*") -> 3430.4 | F18: =SUMIFS(majandusnäitajad_el._kohta,maakond,$B18,aasta,F$13,majandussektorid,"Teenused*") -> 3467.4 | G18: =SUMIFS(majandusnäitajad_el._kohta,maakond,$B18,aasta,G$13,majandussektorid,"Teenused*") -> 3558.89 | H18: =SUMIFS(majandusnäitajad_el._kohta,maakond,$B18,aasta,H$13,majandussektorid,"Teenused*") -> 3946.61 | I18: =SUMIFS(majandusnäitajad_el._kohta,maakond,$B18,aasta,I$13,majandussektorid,"Teenused*") -> 4594.44 | J18: =SUMIFS(majandusnäitajad_el._kohta,maakond,$B18,aasta,J$13,majandussektorid,"Teenused*") -> 5090.47 | M18: Jõgeva maakond | N18: 2353.05 | O18: 2385.16 | P18: 2294.43 | Q18: 2624.43 | R18: 2503.35 | S18: 3292.48 | T18: 3955.49 | U18: 4348.51
B19: Lääne maakond | C19: =SUMIFS(majandusnäitajad_el._kohta,maakond,$B19,aasta,C$13,majandussektorid,"Teenused*") -> 3690.87 | D19: =SUMIFS(majandusnäitajad_el._kohta,maakond,$B19,aasta,D$13,majandussektorid,"Teenused*") -> 3839.25 | E19: =SUMIFS(majandusnäitajad_el._kohta,maakond,$B19,aasta,E$13,majandussektorid,"Teenused*") -> 3890.15 | F19: =SUMIFS(majandusnäitajad_el._kohta,maakond,$B19,aasta,F$13,majandussektorid,"Teenused*") -> 3852.1 | G19: =SUMIFS(majandusnäitajad_el._kohta,maakond,$B19,aasta,G$13,majandussektorid,"Teenused*") -> 3632.22 | H19: =SUMIFS(majandusnäitajad_el._kohta,maakond,$B19,aasta,H$13,majandussektorid,"Teenused*") -> 3948.4 | I19: =SUMIFS(majandusnäitajad_el._kohta,maakond,$B19,aasta,I$13,majandussektorid,"Teenused*") -> 5118.67 | J19: =SUMIFS(majandusnäitajad_el._kohta,maakond,$B19,aasta,J$13,majandussektorid,"Teenused*") -> 5584.43 | M19: Järva maakond | N19: 3273.62 | O19: 3274.03 | P19: 3430.4 | Q19: 3467.4 | R19: 3558.89 | S19: 3946.61 | T19: 4594.44 | U19: 5090.47
B20: Lääne-Viru maakond | C20: =SUMIFS(majandusnäitajad_el._kohta,maakond,$B20,aasta,C$13,majandussektorid,"Teenused*") -> 3596.66 | D20: =SUMIFS(majandusnäitajad_el._kohta,maakond,$B20,aasta,D$13,majandussektorid,"Teenused*") -> 3224.33 | E20: =SUMIFS(majandusnäitajad_el._kohta,maakond,$B20,aasta,E$13,majandussektorid,"Teenused*") -> 3165.16 | F20: =SUMIFS(majandusnäitajad_el._kohta,maakond,$B20,aasta,F$13,majandussektorid,"Teenused*") -> 3436.71 | G20: =SUMIFS(majandusnäitajad_el._kohta,maakond,$B20,aasta,G$13,majandussektorid,"Teenused*") -> 3521.95 | H20: =SUMIFS(majandusnäitajad_el._kohta,maakond,$B20,aasta,H$13,majandussektorid,"Teenused*") -> 3913.96 | I20: =SUMIFS(majandusnäitajad_el._kohta,maakond,$B20,aasta,I$13,majandussektorid,"Teenused*") -> 4043.42 | J20: =SUMIFS(majandusnäitajad_el._kohta,maakond,$B20,aasta,J$13,majandussektorid,"Teenused*") -> 4385.67 | M20: Lääne maakond | N20: 3690.87 | O20: 3839.25 | P20: 3890.15 | Q20: 3852.1 | R20: 3632.22 | S20: 3948.4 | T20: 5118.67 | U20: 5584.43
B21: Põlva maakond | C21: =SUMIFS(majandusnäitajad_el._kohta,maakond,$B21,aasta,C$13,majandussektorid,"Teenused*") -> 2350.67 | D21: =SUMIFS(majandusnäitajad_el._kohta,maakond,$B21,aasta,D$13,majandussektorid,"Teenused*") -> 2927.45 | E21: =SUMIFS(majandusnäitajad_el._kohta,maakond,$B21,aasta,E$13,majandussektorid,"Teenused*") -> 2967.69 | F21: =SUMIFS(majandusnäitajad_el._kohta,maakond,$B21,aasta,F$13,majandussektorid,"Teenused*") -> 3293.61 | G21: =SUMIFS(majandusnäitajad_el._kohta,maakond,$B21,aasta,G$13,majandussektorid,"Teenused*") -> 3252.18 | H21: =SUMIFS(majandusnäitajad_el._kohta,maakond,$B21,aasta,H$13,majandussektorid,"Teenused*") -> 3542.54 | I21: =SUMIFS(majandusnäitajad_el._kohta,maakond,$B21,aasta,I$13,majandussektorid,"Teenused*") -> 3975.09 | J21: =SUMIFS(majandusnäitajad_el._kohta,maakond,$B21,aasta,J$13,majandussektorid,"Teenused*") -> 4368.15 | M21: Lääne-Viru maakond | N21: 3596.66 | O21: 3224.33 | P21: 3165.16 | Q21: 3436.71 | R21: 3521.95 | S21: 3913.96 | T21: 4043.42 | U21: 4385.67
B22: Pärnu maakond | C22: =SUMIFS(majandusnäitajad_el._kohta,maakond,$B22,aasta,C$13,majandussektorid,"Teenused*") -> 4578.14 | D22: =SUMIFS(majandusnäitajad_el._kohta,maakond,$B22,aasta,D$13,majandussektorid,"Teenused*") -> 4589.19 | E22: =SUMIFS(majandusnäitajad_el._kohta,maakond,$B22,aasta,E$13,majandussektorid,"Teenused*") -> 4793.73 | F22: =SUMIFS(majandusnäitajad_el._kohta,maakond,$B22,aasta,F$13,majandussektorid,"Teenused*") -> 5217.91 | G22: =SUMIFS(majandusnäitajad_el._kohta,maakond,$B22,aasta,G$13,majandussektorid,"Teenused*") -> 5566.35 | H22: =SUMIFS(majandusnäitajad_el._kohta,maakond,$B22,aasta,H$13,majandussektorid,"Teenused*") -> 5831.34 | I22: =SUMIFS(majandusnäitajad_el._kohta,maakond,$B22,aasta,I$13,majandussektorid,"Teenused*") -> 6584.96 | J22: =SUMIFS(majandusnäitajad_el._kohta,maakond,$B22,aasta,J$13,majandussektorid,"Teenused*") -> 7086.16 | M22: Põlva maakond | N22: 2350.67 | O22: 2927.45 | P22: 2967.69 | Q22: 3293.61 | R22: 3252.18 | S22: 3542.54 | T22: 3975.09 | U22: 4368.15
B23: Rapla maakond | C23: =SUMIFS(majandusnäitajad_el._kohta,maakond,$B23,aasta,C$13,majandussektorid,"Teenused*") -> 2725.4 | D23: =SUMIFS(majandusnäitajad_el._kohta,maakond,$B23,aasta,D$13,majandussektorid,"Teenused*") -> 3559.84 | E23: =SUMIFS(majandusnäitajad_el._kohta,maakond,$B23,aasta,E$13,majandussektorid,"Teenused*") -> 3610.85 | F23: =SUMIFS(majandusnäitajad_el._kohta,maakond,$B23,aasta,F$13,majandussektorid,"Teenused*") -> 3849.17 | G23: =SUMIFS(majandusnäitajad_el._kohta,maakond,$B23,aasta,G$13,majandussektorid,"Teenused*") -> 4026.88 | H23: =SUMIFS(majandusnäitajad_el._kohta,maakond,$B23,aasta,H$13,majandussektorid,"Teenused*") -> 4539.83 | I23: =SUMIFS(majandusnäitajad_el._kohta,maakond,$B23,aasta,I$13,majandussektorid,"Teenused*") -> 5388.75 | J23: =SUMIFS(majandusnäitajad_el._kohta,maakond,$B23,aasta,J$13,majandussektorid,"Teenused*") -> 5838.01 | M23: Pärnu maakond | N23: 4578.14 | O23: 4589.19 | P23: 4793.73 | Q23: 5217.91 | R23: 5566.35 | S23: 5831.34 | T23: 6584.96 | U23: 7086.16
B24: Saare maakond | C24: =SUMIFS(majandusnäitajad_el._kohta,maakond,$B24,aasta,C$13,majandussektorid,"Teenused*") -> 4601.23 | D24: =SUMIFS(majandusnäitajad_el._kohta,maakond,$B24,aasta,D$13,majandussektorid,"Teenused*") -> 4950.18 | E24: =SUMIFS(majandusnäitajad_el._kohta,maakond,$B24,aasta,E$13,majandussektorid,"Teenused*") -> 5069.59 | F24: =SUMIFS(majandusnäitajad_el._kohta,maakond,$B24,aasta,F$13,majandussektorid,"Teenused*") -> 5655.4 | G24: =SUMIFS(majandusnäitajad_el._kohta,maakond,$B24,aasta,G$13,majandussektorid,"Teenused*") -> 7466.32 | H24: =SUMIFS(majandusnäitajad_el._kohta,maakond,$B24,aasta,H$13,majandussektorid,"Teenused*") -> 6402.26 | I24: =SUMIFS(majandusnäitajad_el._kohta,maakond,$B24,aasta,I$13,majandussektorid,"Teenused*") -> 7297.7 | J24: =SUMIFS(majandusnäitajad_el._kohta,maakond,$B24,aasta,J$13,majandussektorid,"Teenused*") -> 7845.84 | M24: Rapla maakond | N24: 2725.4 | O24: 3559.84 | P24: 3610.85 | Q24: 3849.17 | R24: 4026.88 | S24: 4539.83 | T24: 5388.75 | U24: 5838.01
B25: Tartu maakond | C25: =SUMIFS(majandusnäitajad_el._kohta,maakond,$B25,aasta,C$13,majandussektorid,"Teenused*") -> 6992.16 | D25: =SUMIFS(majandusnäitajad_el._kohta,maakond,$B25,aasta,D$13,majandussektorid,"Teenused*") -> 7252.65 | E25: =SUMIFS(majandusnäitajad_el._kohta,maakond,$B25,aasta,E$13,majandussektorid,"Teenused*") -> 7755.01 | F25: =SUMIFS(majandusnäitajad_el._kohta,maakond,$B25,aasta,F$13,majandussektorid,"Teenused*") -> 8128.58 | G25: =SUMIFS(majandusnäitajad_el._kohta,maakond,$B25,aasta,G$13,majandussektorid,"Teenused*") -> 9359.32 | H25: =SUMIFS(majandusnäitajad_el._kohta,maakond,$B25,aasta,H$13,majandussektorid,"Teenused*") -> 10273.17 | I25: =SUMIFS(majandusnäitajad_el._kohta,maakond,$B25,aasta,I$13,majandussektorid,"Teenused*") -> 10974.25 | J25: =SUMIFS(majandusnäitajad_el._kohta,maakond,$B25,aasta,J$13,majandussektorid,"Teenused*") -> 12031.48 | M25: Saare maakond | N25: 4601.23 | O25: 4950.18 | P25: 5069.59 | Q25: 5655.4 | R25: 7466.32 | S25: 6402.26 | T25: 7297.7 | U25: 7845.84
... B28: Võru maakond | C28: =SUMIFS(majandusnäitajad_el._kohta,maakond,$B28,aasta,C$13,majandussektorid,"Teenused*") -> 3257.07 | D28: =SUMIFS(majandusnäitajad_el._kohta,maakond,$B28,aasta,D$13,majandussektorid,"Teenused*") -> 3251.94 | E28: =SUMIFS(majandusnäitajad_el._kohta,maakond,$B28,aasta,E$13,majandussektorid,"Teenused*") -> 3203.79 | F28: =SUMIFS(majandusnäitajad_el._kohta,maakond,$B28,aasta,F$13,majandussektorid,"Teenused*") -> 3149.04 | G28: =SUMIFS(majandusnäitajad_el._kohta,maakond,$B28,aasta,G$13,majandussektorid,"Teenused*") -> 3495.72 | H28: =SUMIFS(majandusnäitajad_el._kohta,maakond,$B28,aasta,H$13,majandussektorid,"Teenused*") -> 3833.16 | I28: =SUMIFS(majandusnäitajad_el._kohta,maakond,$B28,aasta,I$13,majandussektorid,"Teenused*") -> 4002.44 | J28: =SUMIFS(majandusnäitajad_el._kohta,maakond,$B28,aasta,J$13,majandussektorid,"Teenused*") -> 4353.59 | M28: Viljandi maakond | N28: 3316.19 | O28: 3990.69 | P28: 3941.15 | Q28: 3984.68 | R28: 4078.32 | S28: 4621.26 | T28: 5416.4 | U28: 5974.85
B29: Standardhälve aasta kohta | C29: =_xlfn.STDEV.P(C14:C28) -> 2691.2922 | D29: =_xlfn.STDEV.P(D14:D28) -> 2877.8593 | E29: =_xlfn.STDEV.P(E14:E28) -> 3124.2975 | F29: =_xlfn.STDEV.P(F14:F28) -> 3221.1979 | G29: =_xlfn.STDEV.P(G14:G28) -> 3482.4437 | H29: =_xlfn.STDEV.P(H14:H28) -> 3746.2583 | I29: =_xlfn.STDEV.P(I14:I28) -> 3969.4552 | J29: =_xlfn.STDEV.P(J14:J28) -> 4328.7348 | M29: Võru maakond | N29: 3257.07 | O29: 3251.94 | P29: 3203.79 | Q29: 3149.04 | R29: 3495.72 | S29: 3833.16 | T29: 4002.44 | U29: 4353.59
B30: Väikseima standardhälbega aasta | C30: 2012

Sheet Ideaal
D1: Rakendus inimese kehakarakteristikute hindamiseks soo, vanuse, pikkuse ja kehakaalu põhjal. Rakendus arvutab ideaalkaalu, kehamassiindeksi (KMI), keharasvaprotsendi, keha tiheduse, ruumala ja kehapindala.
A3: Sisestada andmed siia
A4: lähteandmed
M8: lühendid | N8: valemid
M9: vanus (t)
C10: Algandmed | E10: Valideerimine: | G10: Andmed tulemuste kontrollimiseks | M10: pikkus (l)
B11: sugu | C11: mees | E11: list (mees/naine) | G11: Sugu | H11: N | I11: M | J11: M | K11: N | M11: kaal (m)
B12: vanus (t) | C12: 54 | D12: aastat | E12: täisarv 17..100 | G12: Vanus | H12: 22 | I12: 20 | J12: 60 | K12: 37 | M12: Ideaalkaal (mid)
B13: pikkus (l) | C13: 175 | D13: cm | E13: arv 150..200 | G13: Pikkus | H13: 165 | I13: 180 | J13: 175 | K13: 160 | L13: cm | M13: rasvaprotsent (r)
B14: kaal (m) | C14: 80 | D14: kg | E14: arv 45..120 | G14: Kaal | H14: 48 | I14: 70 | J14: 90 | K14: 78 | L14: kg | M14: kehamassiindeks (kind)
M15: tihedus (p)
C16: Tulemused | G16: tulemused | M16: pindala (S)
B17: Ideaalkaal (mid) | C17: =(IF(sugu="naine",(3*pikkus__l-450+vanus__t)*0.225+40.5,(3*pikkus__l-450+vanus__t)*0.25+45)) -> 77.25 | D17: kg | G17: Ideaalne kaal | H17: 55.6 | I17: 72.5 | J17: 78.8 | K17: 55.6 | L17: kg | M17: ruumala (V)
B18: rasvaprotsent (r) | C18: =IF((IF(sugu="naine",((kaal__m-Ideaalkaal__mid)/kaal__m)*100+22,((kaal__m-Ideaalkaal__mid)/kaal__m)*100+15))<0,0,IF(sugu="naine",((kaal__m-Ideaalkaal__mid)/kaal__m)*100+22,((kaal__m-Ideaalkaal__mid)/kaal__m)*100+15)) -> 18.4375 | G18: Rasvaprotsent | H18: 6.2 | I18: 11.4 | J18: 27.5 | K18: 50.8 | L18: %
B19: kehamassiindeks (kind) | C19: =(kaal__m/((pikkus__l/100)^2)) -> 26.122449 | G19: Kehamassiindeks | H19: 17.6 | I19: 21.6 | J19: 29.4 | K19: 30.5
B20: tihedus (p) | C20: =8.9*rasvaprotsent__r+11*(100-rasvaprotsent__r) -> 1061.2812 | D20: kg/m3 | G20: Tihedus | H20: 1086.9 | I20: 1076 | J20: 1042.3 | K20: 993.4 | L20: kg/m3
B21: y | C21: =(35.75-LOG(kaal__m))/53.2 -> 0.63622011 | G21: Pindala | H21: 1.5 | I21: 1.9 | J21: 2.1 | K21: 1.9 | L21: m2
B22: pindala (S) | C22: =(((1000*kaal__m)^y)*pikkus__l^0.3)/3118.2 -> 1.9881627 | D22: m2 | G22: Ruumala | H22: 44.2 | I22: 65.1 | J22: 86.4 | K22: 78.5 | L22: dm3
B23: ruumala (V) | C23: =(1000*kaal__m)/tihedus__p -> 75.380584 | D23: dm3 | G23: Hinnang | H23: kõhn | I23: normaalne | J23: ülekaalus | K23: ei või olla
B24: hinnang | C24: {=_xlfn.IFS(kehamassiindeks__kind<18,"kõhn",AND(18<=kehamassiindeks__kind,kehamassiindeks__kind<=25),"normaalne",AND(25<kehamassiindeks__kind,kehamassiindeks__kind<=30),"ülekaalus",kehamassiindeks__kind>30,"ei või olla")} -> ülekaalus
A25: hinnang otsifuntsioonide abil | C25: =INDEX(tabel_kmi,MATCH(pikkus__l,kõik_pikkused,1),MATCH(kaal__m,kõik_kaalud,1)) -> ülekaalus | D25: =_xlfn.FORMULATEXT(C25) -> =INDEX(tabel_kmi;MATCH(pikkus__l;kõik_pikkused;1);MATCH(kaal__m;kõik_kaalud;1))
S28: kaalud
R29: =sõnaline_hinnang -> ülekaalus | S29: 45 | T29: 50 | U29: 55 | V29: 60 | W29: 65 | X29: 70 | Y29: 75 | Z29: 80 | AA29: 85 | AB29: 90 | AC29: 95 | AD29: 100 | AE29: 105 | AF29: 110 | AG29: 115 | AH29: 120
R30: 150 | S30: normaalne | T30: normaalne | U30: normaalne | V30: ülekaalus | W30: ülekaalus | X30: ei või olla | Y30: ei või olla | Z30: ei või olla | AA30: ei või olla | AB30: ei või olla | AC30: ei või olla | AD30: ei või olla | AE30: ei või olla | AF30: ei või olla | AG30: ei või olla | AH30: ei või olla
G31: 54 a. 80kg mehe ruumala ja sõnaline hinnang Data Table abil | L31: 54 a. 80kg inimese tihedus erinevate pikkuste korral Data Table abil | R31: 155 | S31: normaalne | T31: normaalne | U31: normaalne | V31: normaalne | W31: ülekaalus | X31: ülekaalus | Y31: ei või olla | Z31: ei või olla | AA31: ei või olla | AB31: ei või olla | AC31: ei või olla | AD31: ei või olla | AE31: ei või olla | AF31: ei või olla | AG31: ei või olla | AH31: ei või olla
R32: 160 | S32: kõhn | T32: normaalne | U32: normaalne | V32: normaalne | W32: ülekaalus | X32: ülekaalus | Y32: ülekaalus | Z32: ei või olla | AA32: ei või olla | AB32: ei või olla | AC32: ei või olla | AD32: ei või olla | AE32: ei või olla | AF32: ei või olla | AG32: ei või olla | AH32: ei või olla
G33: a) | L33: b) | R33: 165 | S33: kõhn | T33: normaalne | U33: normaalne | V33: normaalne | W33: normaalne | X33: ülekaalus | Y33: ülekaalus | Z33: ülekaalus | AA33: ei või olla | AB33: ei või olla | AC33: ei või olla | AD33: ei või olla | AE33: ei või olla | AF33: ei või olla | AG33: ei või olla | AH33: ei või olla
N34: tihedus | R34: 170 | S34: kõhn | T34: kõhn | U34: normaalne | V34: normaalne | W34: normaalne | X34: normaalne | Y34: ülekaalus | Z34: ülekaalus | AA34: ülekaalus | AB34: ei või olla | AC34: ei või olla | AD34: ei või olla | AE34: ei või olla | AF34: ei või olla | AG34: ei või olla | AH34: ei või olla
H35: pikkus | I35: =C23 -> 75.380584 | J35: =C24 -> ülekaalus | M35: =C20 -> 1061.2812 | N35: mees | O35: naine | R35: 175 | S35: kõhn | T35: kõhn | U35: kõhn | V35: normaalne | W35: normaalne | X35: normaalne | Y35: normaalne | Z35: ülekaalus | AA35: ülekaalus | AB35: ülekaalus | AC35: ei või olla | AD35: ei või olla | AE35: ei või olla | AF35: ei või olla | AG35: ei või olla | AH35: ei või olla
H36: 150 | I36: 79.046502 | J36: ei või olla | M36: 150 | N36: 1012.0625 | O36: 982.00625 | R36: 180 | S36: kõhn | T36: kõhn | U36: kõhn | V36: normaalne | W36: normaalne | X36: normaalne | Y36: normaalne | Z36: normaalne | AA36: ülekaalus | AB36: ülekaalus | AC36: ülekaalus | AD36: ei või olla | AE36: ei või olla | AF36: ei või olla | AG36: ei või olla | AH36: ei või olla
H37: 155 | I37: 78.285068 | J37: ei või olla | M37: 155 | N37: 1021.9062 | O37: 990.86563 | R37: 185 | S37: kõhn | T37: kõhn | U37: kõhn | V37: kõhn | W37: normaalne | X37: normaalne | Y37: normaalne | Z37: normaalne | AA37: normaalne | AB37: ülekaalus | AC37: ülekaalus | AD37: ülekaalus | AE37: ei või olla | AF37: ei või olla | AG37: ei või olla | AH37: ei või olla
H38: 160 | I38: 77.538163 | J38: ei või olla | M38: 160 | N38: 1031.75 | O38: 999.725 | R38: 190 | S38: kõhn | T38: kõhn | U38: kõhn | V38: kõhn | W38: normaalne | X38: normaalne | Y38: normaalne | Z38: normaalne | AA38: normaalne | AB38: normaalne | AC38: ülekaalus | AD38: ülekaalus | AE38: ülekaalus | AF38: ei või olla | AG38: ei või olla | AH38: ei või olla
H39: 165 | I39: 76.805376 | J39: ülekaalus | M39: 165 | N39: 1041.5938 | O39: 1008.5844 | R39: 195 | S39: kõhn | T39: kõhn | U39: kõhn | V39: kõhn | W39: kõhn | X39: normaalne | Y39: normaalne | Z39: normaalne | AA39: normaalne | AB39: normaalne | AC39: normaalne | AD39: ülekaalus | AE39: ülekaalus | AF39: ülekaalus | AG39: ei või olla | AH39: ei või olla
H40: 170 | I40: 76.08631 | J40: ülekaalus | M40: 170 | N40: 1051.4375 | O40: 1017.4438 | R40: 200 | S40: kõhn | T40: kõhn | U40: kõhn | V40: kõhn | W40: kõhn | X40: kõhn | Y40: normaalne | Z40: normaalne | AA40: normaalne | AB40: normaalne | AC40: normaalne | AD40: normaalne | AE40: ülekaalus | AF40: ülekaalus | AG40: ülekaalus | AH40: ülekaalus
H41: 175 | I41: 75.380584 | J41: ülekaalus | M41: 175 | N41: 1061.2812 | O41: 1026.3031
H42: 180 | I42: 74.687828 | J42: normaalne | M42: 180 | N42: 1071.125 | O42: 1035.1625
H43: 185 | I43: 74.00769 | J43: normaalne | M43: 185 | N43: 1080.9688 | O43: 1044.0219
H44: 190 | I44: 73.339827 | J44: normaalne | M44: 190 | N44: 1090.8125 | O44: 1052.8812
H45: 195 | I45: 72.727273 | J45: normaalne | M45: 195 | N45: 1100 | O45: 1061.7406
H46: 200 | I46: 72.727273 | J46: normaalne | M46: 200 | N46: 1100 | O46: 1070.6

Sheet Töötajad
A1: Nimi | B1: Isikukood | C1: Osakond | D1: Amet | E1: Palk
A2: Olav Berk | B2: 36010010961 | C2: Tootmine | D2: tööline | E2: 1160
A3: Aasa Randla | B3: 46206131090 | C3: Majandus | D3: koristaja | E3: 960
A4: Riho Kuusk | B4: 36209121746 | C4: Tootmine | D4: tööline | E4: 1380
A5: Marko Erikson | B5: 36304040224 | C5: Tootmine | D5: meister | E5: 1840
A6: Mirja Bergmann | B6: 46309091292 | C6: Majandus | D6: koristaja | E6: 2540
A7: Aadu Pulk | B7: 36310140329 | C7: Transport | D7: valvur | E7: 900
A8: Einar Ehala | B8: 36404211932 | C8: Tootmine | D8: treial | E8: 1360
A9: Hendrik Kanter | B9: 36408291485 | C9: Tootmine | D9: juhataja | E9: 4360
A10: Leida Jaanus | B10: 46501120761 | C10: Tootmine | D10: tööline | E10: 1280
A11: Anton Meister | B11: 36502051451 | C11: Ladu | D11: juhataja | E11: 3020
A12: Madis Maasalu | B12: 36503080641 | C12: Tootmine | D12: tööline | E12: 1440
A13: Sirje Härm | B13: 46505111762 | C13: Ost | D13: sekretär | E13: 1140
... A100: Erika Kasemets | B100: 60211241218 | C100: Müük | D100: sekretär | E100: 1300

Sheet Rahvastik
C3: 2012 | D3: 2013 | E3: 2014 | F3: 2015 | G3: 2016 | H3: 2017 | I3: 2018 | J3: 2019
B4: Harju maakond | C4: 566741 | D4: 567967 | E4: 572103 | F4: 575601 | G4: 576265 | H4: 582556 | I4: 589610 | J4: 598059
B5: Hiiu maakond | C5: 8620 | D5: 8638 | E5: 8589 | F5: 8582 | G5: 9348 | H5: 9335 | I5: 9387 | J5: 9387
B6: Ida-Viru maakond | C6: 153716 | D6: 151909 | E6: 149483 | F6: 147597 | G6: 146506 | H6: 143880 | I6: 138266 | J6: 136240
B7: Jõgeva maakond | C7: 31967 | D7: 31587 | E7: 31145 | F7: 30841 | G7: 31298 | H7: 30840 | I7: 29119 | J7: 28734
B8: Järva maakond | C8: 31204 | D8: 30913 | E8: 30425 | F8: 30109 | G8: 30709 | H8: 30378 | I8: 30661 | J8: 30286
B9: Lääne maakond | C9: 24734 | D9: 24622 | E9: 24323 | F9: 24070 | G9: 24580 | H9: 24301 | I9: 20646 | J9: 20507
B10: Lääne-Viru maakond | C10: 61154 | D10: 60518 | E10: 59583 | F10: 59039 | G10: 59467 | H10: 58856 | I10: 59791 | J10: 59325
B11: Põlva maakond | C11: 28026 | D11: 27816 | E11: 27641 | F11: 27438 | G11: 28218 | H11: 27963 | I11: 25290 | J11: 25006
B12: Pärnu maakond | C12: 84388 | D12: 83677 | E12: 82829 | F12: 82349 | G12: 82997 | H12: 82535 | I12: 85756 | J12: 85938
B13: Rapla maakond | C13: 35503 | D13: 35069 | E13: 34676 | F13: 34436 | G13: 34148 | H13: 34085 | I13: 33299 | J13: 33311
B14: Saare maakond | C14: 31835 | D14: 31815 | E14: 31756 | F14: 31706 | G14: 33481 | H14: 33307 | I14: 33231 | J14: 33108
B15: Tartu maakond | C15: 153479 | D15: 153100 | E15: 152188 | F15: 151377 | G15: 145003 | H15: 145550 | I15: 151122 | J15: 152977
... B18: Võru maakond | C18: 34178 | D18: 33826 | E18: 33426 | F18: 33172 | G18: 33973 | H18: 33505 | I18: 36133 | J18: 35782
